Workbook
Name CONTAINS: LAMBDA(cell, range, NOT(ISERROR(MATCH(cell,range,0))))

Sheet CALLOUT 26
A1: T - Tardy TE - Excused Tardy A - Absent AE - Excused Absence BLUE - did not report to Angie BLACK - reported to Angie Absent +4 Tardy +1 | C1: DO NOT RE-SORT EMPLOYEE NAMES! Add new employees to New Employee Sections
A2: CALLOUTS AND TARDIES | B2: PTO Left | C2: 2025 Totals | I2: GRACE | M2: January | AS2: February | BV2: March | DB2: April | EG2: May | FM2: June | GR2: July | HX2: August | JD2: September | KI2: October | LO2: November | MT2: December
A3: Dates of call outs | C3: A | D3: AE | E3: T | F3: TE | G3: A% | H3: T% | I3: POINTS | J3: UR - T | K3: UR - A | M3: 1/1 | N3: 1/2 | O3: 1/3 | P3: 1/4 | Q3: 1/5 | R3: 1/6 | S3: 1/7 | T3: 1/8 | U3: 1/9 | V3: 1/10 | W3: 1/11 | X3: 1/12 | Y3: 1/13 | Z3: 1/14 | AA3: 1/15 | AB3: 1/16 | AC3: 1/17 | AD3: 1/18 | AE3: 1/19 | AF3: 1/20 | AG3: 1/21 | AH3: 1/22 | AI3: 1/23 | AJ3: 1/24 | AK3: 1/25 | AL3: 1/26 | AM3: 1/27 | AN3: 1/28 | AO3: 1/29 | AP3: 1/30 | AQ3: 1/31 | AS3: 2/1 | AT3: 2/2 | AU3: 2/3 | AV3: 2/4 | AW3: 2/5 | AX3: 2/6 | AY3: 2/7 | AZ3: 2/8 | BA3: 2/9 | BB3: 2/10 | BC3: 2/11 | BD3: 2/12 | BE3: 2/13 | BF3: 2/14 | BG3: 2/15 | BH3: 2/16 | BI3: 2/17 | BJ3: 2/18 | BK3: 2/19 | BL3: 2/20 | BM3: 2/21 | BN3: 2/22 | BO3: 2/23 | BP3: 2/24 | BQ3: 2/25 | BR3: 2/26 | BS3: 2/27 | BT3: 2/28 | BV3: 3/1 | BW3: 3/2 | BX3: 3/3 | BY3: 3/4 | BZ3: 3/5 | CA3: 3/6 | CB3: 3/7 | CC3: 3/8 | CD3: 3/9 | CE3: 3/10 | CF3: 3/11 | CG3: 3/12 | CH3: 3/13 | CI3: 3/14 | CJ3: 3/15 | CK3: 3/16 | CL3: 3/17 | CM3: 3/18 | CN3: 3/19 | CO3: 3/20 | CP3: 3/21 | CQ3: 3/22 | CR3: 3/23 | CS3: 3/24 | CT3: 3/25 | CU3: 3/26 | CV3: 3/27 | CW3: 3/28 | CX3: 3/29 | CY3: 3/30 | CZ3: 3/31 | DB3: 4/1 | DC3: 4/2 | DD3: 4/3 | DE3: 4/4 | DF3: 4/5 | DG3: 4/6 | DH3: 4/7 | DI3: 4/8 | DJ3: 4/9 | DK3: 4/10 | DL3: 4/11 | DM3: 4/12 | DN3: 4/13 | DO3: 4/14 | DP3: 4/15 | DQ3: 4/16 | DR3: 4/17 | DS3: 4/18 | DT3: 4/19 | DU3: 4/20 | DV3: 4/21 | DW3: 4/22 | DX3: 4/23 | DY3: 4/24 | DZ3: 4/25 | EA3: 4/26 | EB3: 4/27 | EC3: 4/28 | ED3: 4/29 | EE3: 4/30 | EG3: 5/1 | EH3: 5/2 | EI3: 5/3 | EJ3: 5/4 | EK3: 5/5 | EL3: 5/6 | EM3: 5/7 | EN3: 5/8 | EO3: 5/9 | EP3: 5/10 | EQ3: 5/11 | ER3: 5/12 | ES3: 5/13 | ET3: 5/14 | EU3: 5/15 | EV3: 5/16 | EW3: 5/17 | EX3: 5/18 | EY3: 5/19 | EZ3: 5/20 | FA3: 5/21 | FB3: 5/22 | FC3: 5/23 | FD3: 5/24 | FE3: 5/25 | FF3: 5/26 | FG3: 5/27 | FH3: 5/28 | FI3: 5/29 | FJ3: 5/30 | FK3: 5/31 | FM3: 6/1 | FN3: 6/2 | FO3: 6/3 | FP3: 6/4 | FQ3: 6/5 | FR3: 6/6 | FS3: 6/7 | FT3: 6/8 | FU3: 6/9 | FV3: 6/10 | FW3: 6/11 | FX3: 6/12 | FY3: 6/13 | FZ3: 6/14 | GA3: 6/15 | GB3: 6/16 | GC3: 6/17 | GD3: 6/18 | GE3: 6/19 | GF3: 6/20 | GG3: 6/21 | GH3: 6/22 | GI3: 6/23 | GJ3: 6/24 | GK3: 6/25 | GL3: 6/26 | GM3: 6/27 | GN3: 6/28 | GO3: 6/29 | GP3: 6/30 | GR3: 7/1 | GS3: 7/2 | GT3: 7/3 | GU3: 7/4 | GV3: 7/5 | GW3: 7/6 | GX3: 7/7 | GY3: 7/8 | GZ3: 7/9 | HA3: 7/10 | HB3: 7/11 | HC3: 7/12 | HD3: 7/13 | HE3: 7/14 | HF3: 7/15 | HG3: 7/16 | HH3: 7/17 | HI3: 7/18 | HJ3: 7/19 | HK3: 7/20 | HL3: 7/21 | HM3: 7/22 | HN3: 7/23 | HO3: 7/24 | HP3: 7/25 | HQ3: 7/26 | HR3: 7/27 | HS3: 7/28 | HT3: 7/29 | HU3: 7/30 | HV3: 7/31 | HX3: 8/1 | HY3: 8/2 | HZ3: 8/3 | IA3: 8/4 | IB3: 8/5 | IC3: 8/6 | ID3: 8/7 | IE3: 8/8 | IF3: 8/9 | IG3: 8/10 | IH3: 8/11 | II3: 8/12 | IJ3: 8/13 | IK3: 8/14 | IL3: 8/15 | IM3: 8/16 | IN3: 8/17 | IO3: 8/18 | IP3: 8/19 | IQ3: 8/20 | IR3: 8/21 | IS3: 8/22 | IT3: 8/23 | IU3: 8/24 | IV3: 8/25 | IW3: 8/26 | IX3: 8/27 | IY3: 8/28 | IZ3: 8/29 | JA3: 8/30 | JB3: 8/31 | JD3: 9/1 | JE3: 9/2 | JF3: 9/3 | JG3: 9/4 | JH3: 9/5 | JI3: 9/6 | JJ3: 9/7 | JK3: 9/8 | JL3: 9/9 | JM3: 9/10 | JN3: 9/11 | JO3: 9/12 | JP3: 9/13 | JQ3: 9/14 | JR3: 9/15 | JS3: 9/16 | JT3: 9/17 | JU3: 9/18 | JV3: 9/19 | JW3: 9/20 | JX3: 9/21 | JY3: 9/22 | JZ3: 9/23 | KA3: 9/24 | KB3: 9/25 | KC3: 9/26 | KD3: 9/27 | KE3: 9/28 | KF3: 9/29 | KG3: 9/30 | KI3: 10/1 | KJ3: 10/2 | KK3: 10/3 | KL3: 10/4 | KM3: 10/5 | KN3: 10/6 | KO3: 10/7 | KP3: 10/8 | KQ3: 10/9 | KR3: 10/10 | KS3: 10/11 | KT3: 10/12 | KU3: 10/13 | KV3: 10/14 | KW3: 10/15 | KX3: 10/16 | KY3: 10/17 | KZ3: 10/18 | LA3: 10/19 | LB3: 10/20 | LC3: 10/21 | LD3: 10/22 | LE3: 10/23 | LF3: 10/24 | LG3: 10/25 | LH3: 10/26 | LI3: 10/27 | LJ3: 10/28 | LK3: 10/29 | LL3: 10/30 | LM3: 10/31 | LO3: 11/1 | LP3: 11/2 | LQ3: 11/3 | LR3: 11/4 | LS3: 11/5 | LT3: 11/6 | LU3: 11/7 | LV3: 11/8 | LW3: 11/9 | LX3: 11/10 | LY3: 11/11 | LZ3: 11/12 | MA3: 11/13 | MB3: 11/14 | MC3: 11/15 | MD3: 11/16 | ME3: 11/17 | MF3: 11/18 | MG3: 11/19 | MH3: 11/20 | MI3: 11/21 | MJ3: 11/22 | MK3: 11/23 | ML3: 11/24 | MM3: 11/25 | MN3: 11/26 | MO3: 11/27 | MP3: 11/28 | MQ3: 11/29 | MR3: 11/30 | MT3: 12/1 | MU3: 12/2 | MV3: 12/3 | MW3: 12/4 | MX3: 12/5 | MY3: 12/6 | MZ3: 12/7 | NA3: 12/8 | NB3: 12/9 | NC3: 12/10 | ND3: 12/11 | NE3: 12/12 | NF3: 12/13 | NG3: 12/14 | NH3: 12/15 | NI3: 12/16 | NJ3: 12/17 | NK3: 12/18 | NL3: 12/19 | NM3: 12/20 | NN3: 12/21 | NO3: 12/22 | NP3: 12/23 | NQ3: 12/24 | NR3: 12/25 | NS3: 12/26 | NT3: 12/27 | NU3: 12/28 | NV3: 12/29 | NW3: 12/30 | NX3: 12/31
A4: Adriana Gutierrez | B4: =IFERROR(__xludf.DUMMYFUNCTION("VLOOKUP(A4, IMPORTRANGE(""https://docs.google.com/spreadsheets/d/1KpTMcNM9m1P7u9qCVzob8p1-RZoC1ejaYs5CdpAbWFY/edit?gid=260580969#gid=260580969"", ""2025 EMP PROFILE DATA!a1:W98""), 22, FALSE)"),"#REF!") -> #REF! | C4: =COUNTIF(M4:NY4, "A") -> 5 | D4: =COUNTIF(M4:NY4, "AE") -> 1 | E4: =countif(M4:NY4, "T") -> 0 | F4: =countif(M4:NY4, "TE") -> 0 | G4: =C4 / NETWORKDAYS(DATE(2025,1,1), TODAY()) -> 0.012626263 | H4: =E4 / NETWORKDAYS(DATE(2025,1,1), TODAY()) -> 0 | I4: =sum(E4+(C4*4)) -> 20 | J4: 0 | K4: 0 | N4: A | AG4: A | BA4: A | BE4: AE | BW4: A | GK4: A
A5: Aislinn Dickey | B5: =IFERROR(__xludf.DUMMYFUNCTION("VLOOKUP(A5, IMPORTRANGE(""https://docs.google.com/spreadsheets/d/1KpTMcNM9m1P7u9qCVzob8p1-RZoC1ejaYs5CdpAbWFY/edit?gid=260580969#gid=260580969"", ""2025 EMP PROFILE DATA!a1:W98""), 22, FALSE)"),"#REF!") -> #REF! | C5: =COUNTIF(M5:NY5, "A") -> 0 | D5: =COUNTIF(M5:NY5, "AE") -> 6 | E5: =countif(M5:NY5, "T") -> 0 | F5: =countif(M5:NY5, "TE") -> 1 | G5: =C5 / NETWORKDAYS(DATE(2025,1,1), TODAY()) -> 0 | H5: =E5 / NETWORKDAYS(DATE(2025,1,1), TODAY()) -> 0 | I5: =sum(E5+(C5*4)) -> 0 | J5: 0 | K5: 0 | S5: AE | BJ5: TE | BW5: AE | CH5: AE | EQ5: AE | FF5: AE | GX5: AE
A6: Alexandra Martin | B6: =IFERROR(__xludf.DUMMYFUNCTION("VLOOKUP(A6, IMPORTRANGE(""https://docs.google.com/spreadsheets/d/1KpTMcNM9m1P7u9qCVzob8p1-RZoC1ejaYs5CdpAbWFY/edit?gid=260580969#gid=260580969"", ""2025 EMP PROFILE DATA!a1:W98""), 22, FALSE)"),"#REF!") -> #REF! | C6: =COUNTIF(M6:NY6, "A") -> 3 | D6: =COUNTIF(M6:NY6, "AE") -> 11 | E6: =countif(M6:NY6, "T") -> 8 | F6: =countif(M6:NY6, "TE") -> 1 | G6: =C6 / NETWORKDAYS(DATE(2025,1,1), TODAY()) -> 0.0075757576 | H6: =E6 / NETWORKDAYS(DATE(2025,1,1), TODAY()) -> 0.02020202 | I6: =sum(E6+(C6*4)) -> 20 | J6: 0 | K6: 0 | AI6: T | AV6: T | BB6: AE | BJ6: A | BW6: AE | BX6: AE | BY6: AE | CG6: T | CM6: TE | CR6: AE | CZ6: AE | DH6: T | DK6: A | DU6: T | DV6: T | EG6: AE | EU6: A | FA6: A | FG6: AE | FH6: AE | FI6: AE | FM6: T | FT6: T | FU6: AE
A7: Alexei Marquez | B7: =IFERROR(__xludf.DUMMYFUNCTION("VLOOKUP(A7, IMPORTRANGE(""https://docs.google.com/spreadsheets/d/1KpTMcNM9m1P7u9qCVzob8p1-RZoC1ejaYs5CdpAbWFY/edit?gid=260580969#gid=260580969"", ""2025 EMP PROFILE DATA!a1:W98""), 22, FALSE)"),"#REF!") -> #REF! | C7: =COUNTIF(M7:NY7, "A") -> 1 | D7: =COUNTIF(M7:NY7, "AE") -> 1 | E7: =countif(M7:NY7, "T") -> 3 | F7: =countif(M7:NY7, "TE") -> 0 | G7: =C7 / NETWORKDAYS(DATE(2025,1,1), TODAY()) -> 0.0025252525 | H7: =E7 / NETWORKDAYS(DATE(2025,1,1), TODAY()) -> 0.0075757576 | I7: =sum(E7+(C7*4)) -> 7 | J7: 0 | K7: 0 | AE7: T | AL7: A | AW7: T | BQ7: T | BW7: AE
A8: Alysia Sanford | B8: =IFERROR(__xludf.DUMMYFUNCTION("VLOOKUP(A8, IMPORTRANGE(""https://docs.google.com/spreadsheets/d/1KpTMcNM9m1P7u9qCVzob8p1-RZoC1ejaYs5CdpAbWFY/edit?gid=260580969#gid=260580969"", ""2025 EMP PROFILE DATA!a1:W98""), 22, FALSE)"),"#REF!") -> #REF! | C8: =COUNTIF(M8:NY8, "A") -> 2 | D8: =COUNTIF(M8:NY8, "AE") -> 2 | E8: =countif(M8:NY8, "T") -> 34 | F8: =countif(M8:NY8, "TE") -> 3 | G8: =C8 / NETWORKDAYS(DATE(2025,1,1), TODAY()) -> 0.0050505051 | H8: =E8 / NETWORKDAYS(DATE(2025,1,1), TODAY()) -> 0.085858586 | I8: =sum(E8+(C8*4)) -> 42 | J8: 0 | K8: 0 | R8: T | S8: T | T8: T | U8: T | AM8: T | AN8: T | AP8: TE | AQ8: T | AT8: T | AU8: T | AV8: T | AW8: T | AX8: T | BA8: T | BC8: T | BD8: T | BE8: T | BI8: T | BK8: TE | BL8: TE | BO8: T | BP8: T | BQ8: T | BW8: T | BY8: T | BZ8: T | CE8: T | CF8: T | CN8: T | DR8: AE | DU8: T | DX8: A | EA8: A | EB8: T | EC8: T | ED8: T | EE8: T | ES8: T | EZ8: AE | FC8: T | FH8: T
A9: Ana Diaz | B9: =IFERROR(__xludf.DUMMYFUNCTION("VLOOKUP(A9, IMPORTRANGE(""https://docs.google.com/spreadsheets/d/1KpTMcNM9m1P7u9qCVzob8p1-RZoC1ejaYs5CdpAbWFY/edit?gid=260580969#gid=260580969"", ""2025 EMP PROFILE DATA!a1:W98""), 22, FALSE)"),"#REF!") -> #REF! | C9: =COUNTIF(M9:NY9, "A") -> 0 | D9: =COUNTIF(M9:NY9, "AE") -> 0 | E9: =countif(M9:NY9, "T") -> 0 | F9: =countif(M9:NY9, "TE") -> 0 | G9: =C9 / NETWORKDAYS(DATE(2025,1,1), TODAY()) -> 0 | H9: =E9 / NETWORKDAYS(DATE(2025,1,1), TODAY()) -> 0 | I9: =sum(E9+(C9*4)) -> 0 | J9: 0 | K9: 0
A10: Ana Livia | B10: =IFERROR(__xludf.DUMMYFUNCTION("VLOOKUP(A10, IMPORTRANGE(""https://docs.google.com/spreadsheets/d/1KpTMcNM9m1P7u9qCVzob8p1-RZoC1ejaYs5CdpAbWFY/edit?gid=260580969#gid=260580969"", ""2025 EMP PROFILE DATA!a1:W98""), 22, FALSE)"),"#REF!") -> #REF! | C10: =COUNTIF(M10:NY10, "A") -> 0 | D10: =COUNTIF(M10:NY10, "AE") -> 0 | E10: =countif(M10:NY10, "T") -> 2 | F10: =countif(M10:NY10, "TE") -> 4 | G10: =C10 / NETWORKDAYS(DATE(2025,1,1), TODAY()) -> 0 | H10: =E10 / NETWORKDAYS(DATE(2025,1,1), TODAY()) -> 0.0050505051 | I10: =sum(E10+(C10*4)) -> 2 | J10: 0 | K10: 0 | CA10: T | DU10: TE | EB10: TE | EK10: T | FQ10: TE | GX10: TE
A11: Angela Fraga | B11: =IFERROR(__xludf.DUMMYFUNCTION("VLOOKUP(A11, IMPORTRANGE(""https://docs.google.com/spreadsheets/d/1KpTMcNM9m1P7u9qCVzob8p1-RZoC1ejaYs5CdpAbWFY/edit?gid=260580969#gid=260580969"", ""2025 EMP PROFILE DATA!a1:W98""), 22, FALSE)"),"#REF!") -> #REF! | C11: =COUNTIF(M11:NY11, "A") -> 0 | D11: =COUNTIF(M11:NY11, "AE") -> 1 | E11: =countif(M11:NY11, "T") -> 1 | F11: =countif(M11:NY11, "TE") -> 0 | G11: =C11 / NETWORKDAYS(DATE(2025,1,1), TODAY()) -> 0 | H11: =E11 / NETWORKDAYS(DATE(2025,1,1), TODAY()) -> 0.0025252525 | I11: =sum(E11+(C11*4)) -> 1 | J11: 0 | K11: 0 | BM11: AE | EU11: T
A12: Angela Lina | B12: =IFERROR(__xludf.DUMMYFUNCTION("VLOOKUP(A12, IMPORTRANGE(""https://docs.google.com/spreadsheets/d/1KpTMcNM9m1P7u9qCVzob8p1-RZoC1ejaYs5CdpAbWFY/edit?gid=260580969#gid=260580969"", ""2025 EMP PROFILE DATA!a1:W98""), 22, FALSE)"),"#REF!") -> #REF! | C12: =COUNTIF(M12:NY12, "A") -> 0 | D12: =COUNTIF(M12:NY12, "AE") -> 0 | E12: =countif(M12:NY12, "T") -> 0 | F12: =countif(M12:NY12, "TE") -> 0 | G12: =C12 / NETWORKDAYS(DATE(2025,1,1), TODAY()) -> 0 | H12: =E12 / NETWORKDAYS(DATE(2025,1,1), TODAY()) -> 0 | I12: =sum(E12+(C12*4)) -> 0 | J12: 0 | K12: 0
A13: Ashley Paredes | B13: =IFERROR(__xludf.DUMMYFUNCTION("VLOOKUP(A13, IMPORTRANGE(""https://docs.google.com/spreadsheets/d/1KpTMcNM9m1P7u9qCVzob8p1-RZoC1ejaYs5CdpAbWFY/edit?gid=260580969#gid=260580969"", ""2025 EMP PROFILE DATA!a1:W98""), 22, FALSE)"),"#REF!") -> #REF! | C13: =COUNTIF(M13:NY13, "A") -> 0 | D13: =COUNTIF(M13:NY13, "AE") -> 2 | E13: =countif(M13:NY13, "T") -> 4 | F13: =countif(M13:NY13, "TE") -> 5 | G13: =C13 / NETWORKDAYS(DATE(2025,1,1), TODAY()) -> 0 | H13: =E13 / NETWORKDAYS(DATE(2025,1,1), TODAY()) -> 0.01010101 | I13: =sum(E13+(C13*4)) -> 4 | J13: 0 | K13: 0 | AB13: T | BK13: TE | BS13: TE | CA13: TE | CD13: AE | CI13: TE | ET13: T | EV13: T | FM13: AE | GA13: T | GI13: TE
A14: Barbara Long | B14: =IFERROR(__xludf.DUMMYFUNCTION("VLOOKUP(A14, IMPORTRANGE(""https://docs.google.com/spreadsheets/d/1KpTMcNM9m1P7u9qCVzob8p1-RZoC1ejaYs5CdpAbWFY/edit?gid=260580969#gid=260580969"", ""2025 EMP PROFILE DATA!a1:W98""), 22, FALSE)"),"#REF!") -> #REF! | C14: =COUNTIF(M14:NY14, "A") -> 4 | D14: =COUNTIF(M14:NY14, "AE") -> 0 | E14: =countif(M14:NY14, "T") -> 3 | F14: =countif(M14:NY14, "TE") -> 0 | G14: =C14 / NETWORKDAYS(DATE(2025,1,1), TODAY()) -> 0.01010101 | H14: =E14 / NETWORKDAYS(DATE(2025,1,1), TODAY()) -> 0.0075757576 | I14: =sum(E14+(C14*4)) -> 19 | J14: 0 | K14: 0 | DH14: T | DI14: A | DU14: A | EE14: A | EG14: A | FR14: T | FX14: T
A15: Bianca Alfonso | B15: =IFERROR(__xludf.DUMMYFUNCTION("VLOOKUP(A15, IMPORTRANGE(""https://docs.google.com/spreadsheets/d/1KpTMcNM9m1P7u9qCVzob8p1-RZoC1ejaYs5CdpAbWFY/edit?gid=260580969#gid=260580969"", ""2025 EMP PROFILE DATA!a1:W98""), 22, FALSE)"),"#REF!") -> #REF! | C15: =COUNTIF(M15:NY15, "A") -> 1 | D15: =COUNTIF(M15:NY15, "AE") -> 0 | E15: =countif(M15:NY15, "T") -> 0 | F15: =countif(M15:NY15, "TE") -> 0 | G15: =C15 / NETWORKDAYS(DATE(2025,1,1), TODAY()) -> 0.0025252525 | H15: =E15 / NETWORKDAYS(DATE(2025,1,1), TODAY()) -> 0 | I15: =sum(E15+(C15*4)) -> 4 | J15: 0 | K15: 0 | FX15: A
A16: Brandon Orange | B16: =IFERROR(__xludf.DUMMYFUNCTION("VLOOKUP(A16, IMPORTRANGE(""https://docs.google.com/spreadsheets/d/1KpTMcNM9m1P7u9qCVzob8p1-RZoC1ejaYs5CdpAbWFY/edit?gid=260580969#gid=260580969"", ""2025 EMP PROFILE DATA!a1:W98""), 22, FALSE)"),"#REF!") -> #REF! | C16: =COUNTIF(M16:NY16, "A") -> 0 | D16: =COUNTIF(M16:NY16, "AE") -> 0 | E16: =countif(M16:NY16, "T") -> 19 | F16: =countif(M16:NY16, "TE") -> 5 | G16: =C16 / NETWORKDAYS(DATE(2025,1,1), TODAY()) -> 0 | H16: =E16 / NETWORKDAYS(DATE(2025,1,1), TODAY()) -> 0.047979798 | I16: =sum(E16+(C16*4)) -> 19 | J16: 0 | K16: 0 | Q16: T | R16: T | AM16: T | AT16: T | BD16: T | BE16: T | BF16: T | BI16: T | BQ16: T | BS16: TE | CE16: T | CF16: TE | CG16: TE | CK16: TE | CO16: TE | CZ16: T | DN16: T | DO16: T | DS16: T | DZ16: T | FF16: T | FJ16: T | GD16: T | GL16: T
A17: Brittany Finch | B17: =IFERROR(__xludf.DUMMYFUNCTION("VLOOKUP(A17, IMPORTRANGE(""https://docs.google.com/spreadsheets/d/1KpTMcNM9m1P7u9qCVzob8p1-RZoC1ejaYs5CdpAbWFY/edit?gid=260580969#gid=260580969"", ""2025 EMP PROFILE DATA!a1:W98""), 22, FALSE)"),"#REF!") -> #REF! | C17: =COUNTIF(M17:NY17, "A") -> 11 | D17: =COUNTIF(M17:NY17, "AE") -> 7 | E17: =countif(M17:NY17, "T") -> 9 | F17: =countif(M17:NY17, "TE") -> 0 | G17: =C17 / NETWORKDAYS(DATE(2025,1,1), TODAY()) -> 0.027777778 | H17: =E17 / NETWORKDAYS(DATE(2025,1,1), TODAY()) -> 0.022727273 | I17: =sum(E17+(C17*4)) -> 53 | J17: 0 | K17: 0 | O17: A | Q17: T | R17: T | T17: A | U17: T | X17: T | Z17: T | AV17: A | AW17: AE | AX17: AE | BA17: AE | CD17: A | CF17: T | CH17: T | CR17: AE | CW17: T | DB17: A | DG17: A | DL17: T | DU17: A | EJ17: A | FA17: A | FB17: A | FV17: A | GH17: AE | GI17: AE | GJ17: AE
A18: Caitlin Quenn | B18: =IFERROR(__xludf.DUMMYFUNCTION("VLOOKUP(A18, IMPORTRANGE(""https://docs.google.com/spreadsheets/d/1KpTMcNM9m1P7u9qCVzob8p1-RZoC1ejaYs5CdpAbWFY/edit?gid=260580969#gid=260580969"", ""2025 EMP PROFILE DATA!a1:W98""), 22, FALSE)"),"#REF!") -> #REF! | C18: =COUNTIF(M18:NY18, "A") -> 0 | D18: =COUNTIF(M18:NY18, "AE") -> 4 | E18: =countif(M18:NY18, "T") -> 3 | F18: =countif(M18:NY18, "TE") -> 0 | G18: =C18 / NETWORKDAYS(DATE(2025,1,1), TODAY()) -> 0 | H18: =E18 / NETWORKDAYS(DATE(2025,1,1), TODAY()) -> 0.0075757576 | I18: =sum(E18+(C18*4)) -> 3 | J18: 0 | K18: 0 | X18: AE | BC18: T | BY18: AE | CG18: AE | DW18: T | EH18: T | GO18: AE
A19: Carmen Chan | B19: =IFERROR(__xludf.DUMMYFUNCTION("VLOOKUP(A19, IMPORTRANGE(""https://docs.google.com/spreadsheets/d/1KpTMcNM9m1P7u9qCVzob8p1-RZoC1ejaYs5CdpAbWFY/edit?gid=260580969#gid=260580969"", ""2025 EMP PROFILE DATA!a1:W98""), 22, FALSE)"),"#REF!") -> #REF! | C19: =COUNTIF(M19:NY19, "A") -> 0 | D19: =COUNTIF(M19:NY19, "AE") -> 0 | E19: =countif(M19:NY19, "T") -> 32 | F19: =countif(M19:NY19, "TE") -> 0 | G19: =C19 / NETWORKDAYS(DATE(2025,1,1), TODAY()) -> 0 | H19: =E19 / NETWORKDAYS(DATE(2025,1,1), TODAY()) -> 0.080808081 | I19: =sum(E19+(C19*4)) -> 32 | J19: 0 | K19: 0 | N19: T | Q19: T | R19: T | BB19: T | BC19: T | BM19: T | BR19: T | BS19: T | BY19: T | CB19: T | CD19: T | CG19: T | CI19: T | CL19: T | CM19: T | CN19: T | CS19: T | DD19: T | DE19: T | DH19: T | DS19: T | DU19: T | DV19: T | DW19: T | EH19: T | EJ19: T | EX19: T | FP19: T | FU19: T | FV19: T | FW19: T | FX19: T
A20: Catherine Ramirez | B20: =IFERROR(__xludf.DUMMYFUNCTION("VLOOKUP(A20, IMPORTRANGE(""https://docs.google.com/spreadsheets/d/1KpTMcNM9m1P7u9qCVzob8p1-RZoC1ejaYs5CdpAbWFY/edit?gid=260580969#gid=260580969"", ""2025 EMP PROFILE DATA!a1:W98""), 22, FALSE)"),"#REF!") -> #REF! | C20: =COUNTIF(M20:NY20, "A") -> 0 | D20: =COUNTIF(M20:NY20, "AE") -> 2 | E20: =countif(M20:NY20, "T") -> 11 | F20: =countif(M20:NY20, "TE") -> 0 | G20: =C20 / NETWORKDAYS(DATE(2025,1,1), TODAY()) -> 0 | H20: =E20 / NETWORKDAYS(DATE(2025,1,1), TODAY()) -> 0.027777778 | I20: =sum(E20+(C20*4)) -> 11 | J20: 0 | K20: 0 | R20: T | T20: AE | X20: T | AA20: T | AF20: T | AV20: AE | BC20: T | BT20: T | CK20: T | CM20: T | DO20: T | DP20: T | FV20: T
A21: Christina Earnest | B21: =IFERROR(__xludf.DUMMYFUNCTION("VLOOKUP(A21, IMPORTRANGE(""https://docs.google.com/spreadsheets/d/1KpTMcNM9m1P7u9qCVzob8p1-RZoC1ejaYs5CdpAbWFY/edit?gid=260580969#gid=260580969"", ""2025 EMP PROFILE DATA!a1:W98""), 22, FALSE)"),"#REF!") -> #REF! | C21: =COUNTIF(M21:NY21, "A") -> 0 | D21: =COUNTIF(M21:NY21, "AE") -> 0 | E21: =countif(M21:NY21, "T") -> 0 | F21: =countif(M21:NY21, "TE") -> 0 | G21: =C21 / NETWORKDAYS(DATE(2025,1,1), TODAY()) -> 0 | H21: =E21 / NETWORKDAYS(DATE(2025,1,1), TODAY()) -> 0 | I21: =sum(E21+(C21*4)) -> 0 | J21: 0 | K21: 0
A22: Crystal Barrom | B22: =IFERROR(__xludf.DUMMYFUNCTION("VLOOKUP(A22, IMPORTRANGE(""https://docs.google.com/spreadsheets/d/1KpTMcNM9m1P7u9qCVzob8p1-RZoC1ejaYs5CdpAbWFY/edit?gid=260580969#gid=260580969"", ""2025 EMP PROFILE DATA!a1:W98""), 22, FALSE)"),"#REF!") -> #REF! | C22: =COUNTIF(M22:NY22, "A") -> 1 | D22: =COUNTIF(M22:NY22, "AE") -> 9 | E22: =countif(M22:NY22, "T") -> 7 | F22: =countif(M22:NY22, "TE") -> 5 | G22: =C22 / NETWORKDAYS(DATE(2025,1,1), TODAY()) -> 0.0025252525 | H22: =E22 / NETWORKDAYS(DATE(2025,1,1), TODAY()) -> 0.017676768 | I22: =sum(E22+(C22*4)) -> 11 | J22: 0 | K22: 0 | Q22: AE | Z22: T | AA22: T | AL22: AE | AP22: AE | AT22: AE | AV22: TE | BY22: TE | CE22: T | CL22: TE | DG22: AE | DJ22: T | EL22: AE | EM22: AE | EX22: A | FM22: TE | FO22: T | FP22: T | FQ22: TE | FV22: T | GJ22: AE | GK22: AE
A23: Cynthia Garcia | B23: =IFERROR(__xludf.DUMMYFUNCTION("VLOOKUP(A23, IMPORTRANGE(""https://docs.google.com/spreadsheets/d/1KpTMcNM9m1P7u9qCVzob8p1-RZoC1ejaYs5CdpAbWFY/edit?gid=260580969#gid=260580969"", ""2025 EMP PROFILE DATA!a1:W98""), 22, FALSE)"),"#REF!") -> #REF! | C23: =COUNTIF(M23:NY23, "A") -> 0 | D23: =COUNTIF(M23:NY23, "AE") -> 0 | E23: =countif(M23:NY23, "T") -> 0 | F23: =countif(M23:NY23, "TE") -> 0 | G23: =C23 / NETWORKDAYS(DATE(2025,1,1), TODAY()) -> 0 | H23: =E23 / NETWORKDAYS(DATE(2025,1,1), TODAY()) -> 0 | I23: =sum(E23+(C23*4)) -> 0 | J23: 0 | K23: 0
A24: Deija Lighon | B24: =IFERROR(__xludf.DUMMYFUNCTION("VLOOKUP(A24, IMPORTRANGE(""https://docs.google.com/spreadsheets/d/1KpTMcNM9m1P7u9qCVzob8p1-RZoC1ejaYs5CdpAbWFY/edit?gid=260580969#gid=260580969"", ""2025 EMP PROFILE DATA!a1:W98""), 22, FALSE)"),"#REF!") -> #REF! | C24: =COUNTIF(M24:NY24, "A") -> 2 | D24: =COUNTIF(M24:NY24, "AE") -> 0 | E24: =countif(M24:NY24, "T") -> 1 | F24: =countif(M24:NY24, "TE") -> 0 | G24: =C24 / NETWORKDAYS(DATE(2025,1,1), TODAY()) -> 0.0050505051 | H24: =E24 / NETWORKDAYS(DATE(2025,1,1), TODAY()) -> 0.0025252525 | I24: =sum(E24+(C24*4)) -> 9 | J24: 0 | K24: 0 | ER24: A | ES24: A | FB24: T
A25: Diana Monterde | B25: =IFERROR(__xludf.DUMMYFUNCTION("VLOOKUP(A25, IMPORTRANGE(""https://docs.google.com/spreadsheets/d/1KpTMcNM9m1P7u9qCVzob8p1-RZoC1ejaYs5CdpAbWFY/edit?gid=260580969#gid=260580969"", ""2025 EMP PROFILE DATA!a1:W98""), 22, FALSE)"),"#REF!") -> #REF! | C25: =COUNTIF(M25:NY25, "A") -> 0 | D25: =COUNTIF(M25:NY25, "AE") -> 3 | E25: =countif(M25:NY25, "T") -> 71 | F25: =countif(M25:NY25, "TE") -> 1 | G25: =C25 / NETWORKDAYS(DATE(2025,1,1), TODAY()) -> 0 | H25: =E25 / NETWORKDAYS(DATE(2025,1,1), TODAY()) -> 0.17929293 | I25: =sum(E25+(C25*4)) -> 71 | J25: 0 | K25: 0 | N25: T | O25: T | S25: T | T25: T | U25: T | V25: T | Y25: T | AF25: T | AI25: T | AL25: T | AM25: T | AO25: T | AQ25: T | AV25: T | AW25: T | AX25: AE | AY25: AE | BA25: T | BD25: T | BF25: T | BH25: T | BJ25: T | BK25: T | BL25: T | BR25: T | BS25: T | BT25: T | BW25: T | BX25: T | CB25: T | CD25: T | CG25: T | CH25: T | CI25: T | CK25: T | CM25: T | CN25: T | CO25: T | CP25: T | CR25: T | CS25: T | CU25: T | CY25: T | CZ25: T | DC25: T | DE25: T | DJ25: T | DN25: T | DP25: T | DQ25: T | DS25: T | DV25: T | DX25: T | DY25: T | DZ25: T | EE25: T | EG25: T | EK25: T | EO25: T | EQ25: T | ER25: T | EY25: T | EZ25: T | FQ25: T | FT25: T | FW25: T | FY25: T | GA25: T | GD25: T | GE25: T | GH25: T | GI25: T | GK25: AE | GL25: TE | GM25: T
A26: Dr. Claudia Lau | B26: =IFERROR(__xludf.DUMMYFUNCTION("VLOOKUP(A26, IMPORTRANGE(""https://docs.google.com/spreadsheets/d/1KpTMcNM9m1P7u9qCVzob8p1-RZoC1ejaYs5CdpAbWFY/edit?gid=260580969#gid=260580969"", ""2025 EMP PROFILE DATA!a1:W98""), 22, FALSE)"),"#REF!") -> #REF! | C26: =COUNTIF(M26:NY26, "A") -> 0 | D26: =COUNTIF(M26:NY26, "AE") -> 1 | E26: =countif(M26:NY26, "T") -> 49 | F26: =countif(M26:NY26, "TE") -> 0 | G26: =C26 / NETWORKDAYS(DATE(2025,1,1), TODAY()) -> 0 | H26: =E26 / NETWORKDAYS(DATE(2025,1,1), TODAY()) -> 0.12373737 | I26: =sum(E26+(C26*4)) -> 49 | J26: 0 | K26: 0 | R26: T | T26: T | U26: AE | X26: T | Y26: T | Z26: T | AA26: T | AB26: T | AF26: T | AI26: T | AL26: T | BZ26: T | CD26: T | CH26: T | CI26: T | CK26: T | CL26: T | CM26: T | CR26: T | CU26: T | CY26: T | CZ26: T | DG26: T | DH26: T | DI26: T | DO26: T | DP26: T | DQ26: T | DU26: T | DX26: T | DY26: T | DZ26: T | EB26: T | EC26: T | EE26: T | EJ26: T | EK26: T | EL26: T | EM26: T | EN26: T | ER26: T | ES26: T | FB26: T | FF26: T | FG26: T | FH26: T | GD26: T | GE26: T | GH26: T | GI26: T
A27: Dr. Ella Scott | B27: =IFERROR(__xludf.DUMMYFUNCTION("VLOOKUP(A27, IMPORTRANGE(""https://docs.google.com/spreadsheets/d/1KpTMcNM9m1P7u9qCVzob8p1-RZoC1ejaYs5CdpAbWFY/edit?gid=260580969#gid=260580969"", ""2025 EMP PROFILE DATA!a1:W98""), 22, FALSE)"),"#REF!") -> #REF! | C27: =COUNTIF(M27:NY27, "A") -> 0 | D27: =COUNTIF(M27:NY27, "AE") -> 0 | E27: =countif(M27:NY27, "T") -> 1 | F27: =countif(M27:NY27, "TE") -> 0 | G27: =C27 / NETWORKDAYS(DATE(2025,1,1), TODAY()) -> 0 | H27: =E27 / NETWORKDAYS(DATE(2025,1,1), TODAY()) -> 0.0025252525 | I27: =sum(E27+(C27*4)) -> 1 | J27: 0 | K27: 0 | DK27: T
A28: Dr. Faro | B28: =IFERROR(__xludf.DUMMYFUNCTION("VLOOKUP(A28, IMPORTRANGE(""https://docs.google.com/spreadsheets/d/1KpTMcNM9m1P7u9qCVzob8p1-RZoC1ejaYs5CdpAbWFY/edit?gid=260580969#gid=260580969"", ""2025 EMP PROFILE DATA!a1:W98""), 22, FALSE)"),"#REF!") -> #REF! | C28: =COUNTIF(M28:NY28, "A") -> 0 | D28: =COUNTIF(M28:NY28, "AE") -> 0 | E28: =countif(M28:NY28, "T") -> 20 | F28: =countif(M28:NY28, "TE") -> 0 | G28: =C28 / NETWORKDAYS(DATE(2025,1,1), TODAY()) -> 0 | H28: =E28 / NETWORKDAYS(DATE(2025,1,1), TODAY()) -> 0.050505051 | I28: =sum(E28+(C28*4)) -> 20 | J28: 0 | K28: 0 | BJ28: T | CG28: T | CS28: T | CZ28: T | DC28: T | DD28: T | DE28: T | DG28: T | DK28: T | DN28: T | DP28: T | DY28: T | EM28: T | EV28: T | FA28: T | FF28: T | FM28: T | FP28: T | GD28: T | GH28: T
A29: Dr. Garcia | B29: =IFERROR(__xludf.DUMMYFUNCTION("VLOOKUP(A29, IMPORTRANGE(""https://docs.google.com/spreadsheets/d/1KpTMcNM9m1P7u9qCVzob8p1-RZoC1ejaYs5CdpAbWFY/edit?gid=260580969#gid=260580969"", ""2025 EMP PROFILE DATA!a1:W98""), 22, FALSE)"),"#REF!") -> #REF! | C29: =COUNTIF(M29:NY29, "A") -> 0 | D29: =COUNTIF(M29:NY29, "AE") -> 0 | E29: =countif(M29:NY29, "T") -> 0 | F29: =countif(M29:NY29, "TE") -> 0 | G29: =C29 / NETWORKDAYS(DATE(2025,1,1), TODAY()) -> 0 | H29: =E29 / NETWORKDAYS(DATE(2025,1,1), TODAY()) -> 0 | I29: =sum(E29+(C29*4)) -> 0 | J29: 0 | K29: 0
A30: Dr. Geist | B30: =IFERROR(__xludf.DUMMYFUNCTION("VLOOKUP(A30, IMPORTRANGE(""https://docs.google.com/spreadsheets/d/1KpTMcNM9m1P7u9qCVzob8p1-RZoC1ejaYs5CdpAbWFY/edit?gid=260580969#gid=260580969"", ""2025 EMP PROFILE DATA!a1:W98""), 22, FALSE)"),"#REF!") -> #REF! | C30: =COUNTIF(M30:NY30, "A") -> 1 | D30: =COUNTIF(M30:NY30, "AE") -> 0 | E30: =countif(M30:NY30, "T") -> 20 | F30: =countif(M30:NY30, "TE") -> 0 | G30: =C30 / NETWORKDAYS(DATE(2025,1,1), TODAY()) -> 0.0025252525 | H30: =E30 / NETWORKDAYS(DATE(2025,1,1), TODAY()) -> 0.050505051 | I30: =sum(E30+(C30*4)) -> 24 | J30: 0 | K30: 0 | Z30: T | AE30: T | BI30: T | BL30: T | BQ30: T | BX30: T | BZ30: T | CD30: T | CE30: T | CK30: A | CL30: T | CP30: T | CR30: T | CS30: T | CT30: T | CV30: T | EE30: T | EY30: T | FH30: T | FU30: T | FW30: T
A31: Dr. Habawel | B31: =IFERROR(__xludf.DUMMYFUNCTION("VLOOKUP(A31, IMPORTRANGE(""https://docs.google.com/spreadsheets/d/1KpTMcNM9m1P7u9qCVzob8p1-RZoC1ejaYs5CdpAbWFY/edit?gid=260580969#gid=260580969"", ""2025 EMP PROFILE DATA!a1:W98""), 22, FALSE)"),"#REF!") -> #REF! | C31: =COUNTIF(M31:NY31, "A") -> 1 | D31: =COUNTIF(M31:NY31, "AE") -> 0 | E31: =countif(M31:NY31, "T") -> 11 | F31: =countif(M31:NY31, "TE") -> 0 | G31: =C31 / NETWORKDAYS(DATE(2025,1,1), TODAY()) -> 0.0025252525 | H31: =E31 / NETWORKDAYS(DATE(2025,1,1), TODAY()) -> 0.027777778 | I31: =sum(E31+(C31*4)) -> 15 | J31: 0 | K31: 0 | AM31: T | BQ31: T | BR31: T | CF31: A | CS31: T | DI31: T | DJ31: T | DK31: T | DR31: T | EK31: T | FG31: T | FH31: T
A32: Dr. Hoh | B32: =IFERROR(__xludf.DUMMYFUNCTION("VLOOKUP(A32, IMPORTRANGE(""https://docs.google.com/spreadsheets/d/1KpTMcNM9m1P7u9qCVzob8p1-RZoC1ejaYs5CdpAbWFY/edit?gid=260580969#gid=260580969"", ""2025 EMP PROFILE DATA!a1:W98""), 22, FALSE)"),"#REF!") -> #REF! | C32: =COUNTIF(M32:NY32, "A") -> 0 | D32: =COUNTIF(M32:NY32, "AE") -> 0 | E32: =countif(M32:NY32, "T") -> 1 | F32: =countif(M32:NY32, "TE") -> 0 | G32: =C32 / NETWORKDAYS(DATE(2025,1,1), TODAY()) -> 0 | H32: =E32 / NETWORKDAYS(DATE(2025,1,1), TODAY()) -> 0.0025252525 | I32: =sum(E32+(C32*4)) -> 1 | J32: 0 | K32: 0 | FG32: T
A33: Dr. Niko Alzate | B33: =IFERROR(__xludf.DUMMYFUNCTION("VLOOKUP(A33, IMPORTRANGE(""https://docs.google.com/spreadsheets/d/1KpTMcNM9m1P7u9qCVzob8p1-RZoC1ejaYs5CdpAbWFY/edit?gid=260580969#gid=260580969"", ""2025 EMP PROFILE DATA!a1:W98""), 22, FALSE)"),"#REF!") -> #REF! | C33: =COUNTIF(M33:NY33, "A") -> 0 | D33: =COUNTIF(M33:NY33, "AE") -> 0 | E33: =countif(M33:NY33, "T") -> 0 | F33: =countif(M33:NY33, "TE") -> 0 | G33: =C33 / NETWORKDAYS(DATE(2025,1,1), TODAY()) -> 0 | H33: =E33 / NETWORKDAYS(DATE(2025,1,1), TODAY()) -> 0 | I33: =sum(E33+(C33*4)) -> 0 | J33: 0 | K33: 0
A34: Dr. Rally | B34: =IFERROR(__xludf.DUMMYFUNCTION("VLOOKUP(A34, IMPORTRANGE(""https://docs.google.com/spreadsheets/d/1KpTMcNM9m1P7u9qCVzob8p1-RZoC1ejaYs5CdpAbWFY/edit?gid=260580969#gid=260580969"", ""2025 EMP PROFILE DATA!a1:W98""), 22, FALSE)"),"#REF!") -> #REF! | C34: =COUNTIF(M34:NY34, "A") -> 0 | D34: =COUNTIF(M34:NY34, "AE") -> 0 | E34: =countif(M34:NY34, "T") -> 22 | F34: =countif(M34:NY34, "TE") -> 0 | G34: =C34 / NETWORKDAYS(DATE(2025,1,1), TODAY()) -> 0 | H34: =E34 / NETWORKDAYS(DATE(2025,1,1), TODAY()) -> 0.055555556 | I34: =sum(E34+(C34*4)) -> 22 | J34: 0 | K34: 0 | Y34: T | AO34: T | BK34: T | BL34: T | BQ34: T | BR34: T | CG34: T | DI34: T | DQ34: T | DU34: T | EE34: T | EH34: T | EU34: T | EX34: T | FA34: T | FH34: T | FI34: T | FP34: T | FQ34: T | GA34: T | GD34: T | GH34: T
A35: Dr. Robertson | B35: =IFERROR(__xludf.DUMMYFUNCTION("VLOOKUP(A35, IMPORTRANGE(""https://docs.google.com/spreadsheets/d/1KpTMcNM9m1P7u9qCVzob8p1-RZoC1ejaYs5CdpAbWFY/edit?gid=260580969#gid=260580969"", ""2025 EMP PROFILE DATA!a1:W98""), 22, FALSE)"),"#REF!") -> #REF! | C35: =COUNTIF(M35:NY35, "A") -> 0 | D35: =COUNTIF(M35:NY35, "AE") -> 3 | E35: =countif(M35:NY35, "T") -> 10 | F35: =countif(M35:NY35, "TE") -> 0 | G35: =C35 / NETWORKDAYS(DATE(2025,1,1), TODAY()) -> 0 | H35: =E35 / NETWORKDAYS(DATE(2025,1,1), TODAY()) -> 0.025252525 | I35: =sum(E35+(C35*4)) -> 10 | J35: 0 | K35: 0 | AJ35: T | BD35: AE | BK35: T | BL35: T | BQ35: T | CG35: T | CN35: T | EM35: AE | EN35: AE | FA35: T | FI35: T | FP35: T | GB35: T
A36: Dr. Sherry Vartanian | B36: =IFERROR(__xludf.DUMMYFUNCTION("VLOOKUP(A36, IMPORTRANGE(""https://docs.google.com/spreadsheets/d/1KpTMcNM9m1P7u9qCVzob8p1-RZoC1ejaYs5CdpAbWFY/edit?gid=260580969#gid=260580969"", ""2025 EMP PROFILE DATA!a1:W98""), 22, FALSE)"),"#REF!") -> #REF! | C36: =COUNTIF(M36:NY36, "A") -> 0 | D36: =COUNTIF(M36:NY36, "AE") -> 5 | E36: =countif(M36:NY36, "T") -> 3 | F36: =countif(M36:NY36, "TE") -> 0 | G36: =C36 / NETWORKDAYS(DATE(2025,1,1), TODAY()) -> 0 | H36: =E36 / NETWORKDAYS(DATE(2025,1,1), TODAY()) -> 0.0075757576 | I36: =sum(E36+(C36*4)) -> 3 | J36: 0 | K36: 0 | AF36: T | AT36: AE | AU36: AE | AW36: AE | AX36: AE | AY36: AE | DP36: T | DV36: T
A37: Esmeralda Alfonso | B37: =IFERROR(__xludf.DUMMYFUNCTION("VLOOKUP(A37, IMPORTRANGE(""https://docs.google.com/spreadsheets/d/1KpTMcNM9m1P7u9qCVzob8p1-RZoC1ejaYs5CdpAbWFY/edit?gid=260580969#gid=260580969"", ""2025 EMP PROFILE DATA!a1:W98""), 22, FALSE)"),"#REF!") -> #REF! | C37: =COUNTIF(M37:NY37, "A") -> 1 | D37: =COUNTIF(M37:NY37, "AE") -> 0 | E37: =countif(M37:NY37, "T") -> 17 | F37: =countif(M37:NY37, "TE") -> 0 | G37: =C37 / NETWORKDAYS(DATE(2025,1,1), TODAY()) -> 0.0025252525 | H37: =E37 / NETWORKDAYS(DATE(2025,1,1), TODAY()) -> 0.042929293 | I37: =sum(E37+(C37*4)) -> 21 | J37: 0 | K37: 0 | Y37: T | AB37: T | CR37: T | CS37: T | CT37: T | CZ37: T | DB37: T | DD37: T | DK37: T | DO37: T | DW37: T | DX37: T | DY37: T | EB37: T | ED37: A | EL37: T | ET37: T | EV37: T
A38: Ethan Young | B38: =IFERROR(__xludf.DUMMYFUNCTION("VLOOKUP(A38, IMPORTRANGE(""https://docs.google.com/spreadsheets/d/1KpTMcNM9m1P7u9qCVzob8p1-RZoC1ejaYs5CdpAbWFY/edit?gid=260580969#gid=260580969"", ""2025 EMP PROFILE DATA!a1:W98""), 22, FALSE)"),"#REF!") -> #REF! | C38: =COUNTIF(M38:NY38, "A") -> 0 | D38: =COUNTIF(M38:NY38, "AE") -> 0 | E38: =countif(M38:NY38, "T") -> 3 | F38: =countif(M38:NY38, "TE") -> 0 | G38: =C38 / NETWORKDAYS(DATE(2025,1,1), TODAY()) -> 0 | H38: =E38 / NETWORKDAYS(DATE(2025,1,1), TODAY()) -> 0.0075757576 | I38: =sum(E38+(C38*4)) -> 3 | J38: 0 | K38: 0 | O38: T | AL38: T | GE38: T
A39: Fidel Fraga | B39: =IFERROR(__xludf.DUMMYFUNCTION("VLOOKUP(A39, IMPORTRANGE(""https://docs.google.com/spreadsheets/d/1KpTMcNM9m1P7u9qCVzob8p1-RZoC1ejaYs5CdpAbWFY/edit?gid=260580969#gid=260580969"", ""2025 EMP PROFILE DATA!a1:W98""), 22, FALSE)"),"#REF!") -> #REF! | C39: =COUNTIF(M39:NY39, "A") -> 1 | D39: =COUNTIF(M39:NY39, "AE") -> 2 | E39: =countif(M39:NY39, "T") -> 6 | F39: =countif(M39:NY39, "TE") -> 0 | G39: =C39 / NETWORKDAYS(DATE(2025,1,1), TODAY()) -> 0.0025252525 | H39: =E39 / NETWORKDAYS(DATE(2025,1,1), TODAY()) -> 0.015151515 | I39: =sum(E39+(C39*4)) -> 10 | J39: 0 | K39: 0 | R39: AE | AW39: T | BW39: T | CO39: A | CW39: T | DI39: T | DR39: T | FU39: AE | GI39: T
A40: Gladys Castro | B40: =IFERROR(__xludf.DUMMYFUNCTION("VLOOKUP(A40, IMPORTRANGE(""https://docs.google.com/spreadsheets/d/1KpTMcNM9m1P7u9qCVzob8p1-RZoC1ejaYs5CdpAbWFY/edit?gid=260580969#gid=260580969"", ""2025 EMP PROFILE DATA!a1:W98""), 22, FALSE)"),"#REF!") -> #REF! | C40: =COUNTIF(M40:NY40, "A") -> 6 | D40: =COUNTIF(M40:NY40, "AE") -> 1 | E40: =countif(M40:NY40, "T") -> 7 | F40: =countif(M40:NY40, "TE") -> 0 | G40: =C40 / NETWORKDAYS(DATE(2025,1,1), TODAY()) -> 0.015151515 | H40: =E40 / NETWORKDAYS(DATE(2025,1,1), TODAY()) -> 0.017676768 | I40: =sum(E40+(C40*4)) -> 31 | J40: 0 | K40: 0 | Z40: T | AA40: A | AH40: T | BD40: A | BJ40: A | BK40: T | BQ40: T | BZ40: T | CN40: T | DB40: AE | DC40: A | DX40: T | EM40: A | EZ40: A
...

Sheet VACATION CALENDAR 26
A1: r-[ | B1: JANUARY | J1: FEBRUARY | R1: MARCH | Z1: APRIL | AH1: MAY | AP1: JUNE | AX1: JULY | BF1: AUGUST | BN1: SEPTEMBER | BV1: OCTOBER | CD1: NOVEMBER | CL1: DECEMBER
B3: SUNDAY | C3: MONDAY | D3: TUESDAY | E3: WEDNESDAY | F3: THURSDAY | G3: FRIDAY | H3: SATURDAY | J3: SUNDAY | K3: MONDAY | L3: TUESDAY | M3: WEDNESDAY | N3: THURSDAY | O3: FRIDAY | P3: SATURDAY | R3: SUNDAY | S3: MONDAY | T3: TUESDAY | U3: WEDNESDAY | V3: THURSDAY | W3: FRIDAY | X3: SATURDAY | Z3: SUNDAY | AA3: MONDAY | AB3: TUESDAY | AC3: WEDNESDAY | AD3: THURSDAY | AE3: FRIDAY | AF3: SATURDAY | AH3: SUNDAY | AI3: MONDAY | AJ3: TUESDAY | AK3: WEDNESDAY | AL3: THURSDAY | AM3: FRIDAY | AN3: SATURDAY | AP3: SUNDAY | AQ3: MONDAY | AR3: TUESDAY | AS3: WEDNESDAY | AT3: THURSDAY | AU3: FRIDAY | AV3: SATURDAY | AX3: SUNDAY | AY3: MONDAY | AZ3: TUESDAY | BA3: WEDNESDAY | BB3: THURSDAY | BC3: FRIDAY | BD3: SATURDAY | BF3: SUNDAY | BG3: MONDAY | BH3: TUESDAY | BI3: WEDNESDAY | BJ3: THURSDAY | BK3: FRIDAY | BL3: SATURDAY | BN3: SUNDAY | BO3: MONDAY | BP3: TUESDAY | BQ3: WEDNESDAY | BR3: THURSDAY | BS3: FRIDAY | BT3: SATURDAY | BV3: SUNDAY | BW3: MONDAY | BX3: TUESDAY | BY3: WEDNESDAY | BZ3: THURSDAY | CA3: FRIDAY | CB3: SATURDAY | CD3: SUNDAY | CE3: MONDAY | CF3: TUESDAY | CG3: WEDNESDAY | CH3: THURSDAY | CI3: FRIDAY | CJ3: SATURDAY | CL3: SUNDAY | CM3: MONDAY | CN3: TUESDAY | CO3: WEDNESDAY | CP3: THURSDAY | CQ3: FRIDAY | CR3: SATURDAY
B4: 28 | C4: 29 | D4: 30 | E4: 31 | F4: 1 | G4: 2 | H4: 3 | J4: 1 | K4: 2 | L4: 3 | M4: 4 | N4: 5 | O4: 6 | P4: 7 | R4: 1 | S4: 2 | T4: 3 | U4: 4 | V4: 5 | W4: 6 | X4: 7 | Y4: 5 | Z4: 5 | AA4: 6 | AB4: 7 | AC4: 8 | AD4: 9 | AE4: 10 | AF4: 11 | AH4: 3 | AI4: 4 | AJ4: 5 | AK4: 6 | AL4: 7 | AM4: 8 | AN4: 9 | AP4: 31 | AQ4: 1 | AR4: 2 | AS4: 3 | AT4: 4 | AU4: 5 | AV4: 6 | AX4: 5 | AY4: 6 | AZ4: 7 | BA4: 8 | BB4: 9 | BC4: 10 | BD4: 11 | BF4: 2 | BG4: 3 | BH4: 4 | BI4: 5 | BJ4: 6 | BK4: 7 | BL4: 8 | BN4: 30 | BO4: 31 | BP4: 1 | BQ4: 2 | BR4: 3 | BS4: 4 | BT4: 5 | BV4: 4 | BW4: 5 | BX4: 6 | BY4: 7 | BZ4: 8 | CA4: 9 | CB4: 10 | CD4: 1 | CE4: 2 | CF4: 3 | CG4: 4 | CH4: 5 | CI4: 6 | CJ4: 7 | CL4: 29 | CM4: 30 | CN4: 1 | CO4: 2 | CP4: 3 | CQ4: 4 | CR4: 5
B5: Megan | C5: Megan | D5: Megan | E5: Megan | F5: Megan | G5: Megan | H5: Megan | J5: Dr Lau | K5: Dr Lau | L5: Dr Lau | M5: Dr Lau | N5: Dr Lau | O5: Dr Lau | P5: Dr Lau | X5: Dr V | AF5: Dr V | AH5: Doc | AI5: Doc | AJ5: Doc | AK5: Doc | AL5: Doc | AM5: Doc | AN5: Doc | AQ5: Doc | AR5: Doc | AS5: Doc | AU5: Doc | BA5: Jenn V | BD5: Brandon | BF5: Dr Rally | BG5: Dr Rally | BH5: Dr Rally | BI5: Dr Rally | BJ5: Dr Rally | BK5: Dr Rally | BL5: Dr Rally | BP5: Dr Niko | BQ5: Dr Niko | BV5: Eric | CA5: Isabelle | CB5: Isabelle | CF5: Doc
B6: Dr Hab | C6: Dr Hab | D6: Dr Hab | E6: Dr Hab | F6: Dr Hab | G6: Dr Hab | H6: Dr Hab | K6: Dr Rally | L6: Dr Rally | M6: Dr Rally | N6: Dr Rally | O6: Dr Rally | P6: Dr Rally | R6: Dr Geist | S6: Dr Geist | Z6: Alysia | AA6: Alysia | AH6: Dr Hoh | AI6: Dr Hoh | AJ6: Dr Hoh | AK6: Dr Hoh | AL6: Dr Hoh | AP6: Angela | AQ6: Angela | AR6: Angela | AS6: Angela | AT6: Angela | AU6: Angela | AV6: Angela | AX6: Dr Scott | AY6: Dr Scott | BL6: Dr Lau | BS6: Dr Scott | BT6: Dr Scott | CB6: Eric
G7: Vero | H7: Vero | P7: Dr Scott | R7: Joseph | S7: Joseph | T7: Joseph | Z7: Dr Rally | AA7: Dr Rally | AH7: Alysia | AI7: Alysia | AL7: Alysia | AM7: Alysia | AN7: Alysia | AV7: Laura | AX7: Dr V | AY7: Dr V | AZ7: Dr V | BA7: Dr V | BB7: Dr V | BC7: Dr V | BD7: Dr V | BF7: Doc | BG7: Doc | BH7: Doc | BI7: Doc | BJ7: Doc | BK7: Doc | BL7: Doc | BN7: Lesly | BO7: Lesly | BP7: Lesly | BQ7: Lesly | BR7: Lesly | BS7: Lesly | BT7: Lesly
C8: Jenn | P8: Alysia | X8: Alysia | AB8: Dre | AC8: Dre | AD8: Dre | AE8: Dre | AF8: Dre | AH8: Vero | AI8: Vero | AP8: Brittany F | AQ8: Brittany F | AV8: Alysia | AX8: Dr Rally | AY8: Dr Rally | AZ8: Dr Rally | BA8: Dr Rally | BB8: Dr Rally | BC8: Dr Rally | BD8: Dr Rally | BL8: Markie | BO8: Diana
B9: Dr Lau | C9: Dr Lau | D9: Dr Lau | N9: Aislinn | W9: Dr Scott | X9: Dr Scott | AE9: Natalie | AF9: Natalie | AH9: Karen | AI9: Karen | AL9: Aislinn | AP9: Diana | AQ9: Diana | AR9: Diana | AS9: Diana | AT9: Diana | AX9: Dr Geist | AY9: Dr Geist | BL9: Ali | BP9: Dr Robertson | BQ9: Dr Robertson | BR9: Dr Robertson | BS9: Dr Robertson | BT9: Dr Robertson
B10: Sierra M | C10: Sierra M | P10: Laura | X10: Diana | AF10: Laura | AN10: Laura | AP10: Zuleyka | AQ10: Zuleyka | AR10: Zuleyka | AS10: Zuleyka | AT10: Zuleyka | AU10: Zuleyka | AV10: Zuleyka | AY10: Lizbeth | BC10: Brittany F | BD10: Brittany F | BF10: Ken | BG10: Ken | BK10: Ken | BL10: Ken | BT10: Ken
B11: Doc | C11: Doc | D11: Doc | E11: Doc | F11: Doc | G11: Doc | H11: Doc | L11: Dr Hoh | M11: Dr Hoh | N11: Dr Hoh | O11: Dr Hoh | P11: Dr Hoh | X11: Laura | AD11: Bianca | AE11: Bianca | AF11: Bianca | AN11: Lizbeth | AQ11: Tay Fox | AR11: Tay Fox | BD11: Dr Alzate | BL11: Lizbeth | BN11: Lesly | BO11: Lesly | BP11: Lesly | BQ11: Lesly | BR11: Lesly | BS11: Lesly | BT11: Lesly
G12: Crystal | M12: Batia | N12: Batia | O12: Batia | P12: Batia | W12: Crystal | AF12: Naomi Folta | AM12: Jess S | AU12: Christina | AV12: Christina | BB12: Aislinn | BC12: Aislinn | BD12: Aislinn | BK12: Fidel | BL12: Fidel | BR12: Dr Scott
G13: Dr V | H13: Dr V | K13: Doc | L13: Doc | M13: Doc | N13: Doc | O13: Doc | P13: Doc | AQ13: Aislinn | AR13: Aislinn | AS13: Aislinn | AT13: Aislinn | AU13: Aislinn | AV13: Aislinn | AZ13: Doc | BB13: Ali | BC13: Ali | BD13: Ali | BF13: Miguel | BG13: Miguel | BH13: Miguel | BR13: Isabelle | BS13: Isabelle | BT13: Isabelle
AT14: Jess Salazar | BB14: Doc | BC14: Lesly | BD14: Lesly | BG14: Brandon
AQ15: Lizbeth | AU15: Kirtlynn | AV15: Kirtlynn | AX15: Alysia | BD15: Markie | BK15: Dr Hab | BL15: Dr Hab | BO15: Brandon | BT15: Dr Lau
AS16: Jenn | BA16: Ken | BD16: Ken | BG16: Isabelle | BH16: Isabelle | BI16: Isabelle | BJ16: Isabelle | BK16: Isabelle | BL16: Isabelle
AV17: Dr Alzate | BC17: Kirtlynn | BD17: Kirtlynn | BL17: Laura
AY18: Yalila | BB18: Jisun | BC18: Jisun | BD18: Jisun
B19: SUNDAY | C19: MONDAY | D19: TUESDAY | E19: WEDNESDAY | F19: THURSDAY | G19: FRIDAY | H19: SATURDAY | J19: SUNDAY | K19: MONDAY | L19: TUESDAY | M19: WEDNESDAY | N19: THURSDAY | O19: FRIDAY | P19: SATURDAY | R19: SUNDAY | S19: MONDAY | T19: TUESDAY | U19: WEDNESDAY | V19: THURSDAY | W19: FRIDAY | X19: SATURDAY | Z19: SUNDAY | AA19: MONDAY | AB19: TUESDAY | AC19: WEDNESDAY | AD19: THURSDAY | AE19: FRIDAY | AF19: SATURDAY | AH19: SUNDAY | AI19: MONDAY | AJ19: TUESDAY | AK19: WEDNESDAY | AL19: THURSDAY | AM19: FRIDAY | AN19: SATURDAY | AP19: SUNDAY | AQ19: MONDAY | AR19: TUESDAY | AS19: WEDNESDAY | AT19: THURSDAY | AU19: FRIDAY | AV19: SATURDAY | AX19: SUNDAY | AY19: MONDAY | AZ19: TUESDAY | BA19: WEDNESDAY | BB19: THURSDAY | BC19: FRIDAY | BD19: SATURDAY | BF19: SUNDAY | BG19: MONDAY | BH19: TUESDAY | BI19: WEDNESDAY | BJ19: THURSDAY | BK19: FRIDAY | BL19: SATURDAY | BN19: SUNDAY | BO19: MONDAY | BP19: TUESDAY | BQ19: WEDNESDAY | BR19: THURSDAY | BS19: FRIDAY | BT19: SATURDAY | BV19: SUNDAY | BW19: MONDAY | BX19: TUESDAY | BY19: WEDNESDAY | BZ19: THURSDAY | CA19: FRIDAY | CB19: SATURDAY | CD19: SUNDAY | CE19: MONDAY | CF19: TUESDAY | CG19: WEDNESDAY | CH19: THURSDAY | CI19: FRIDAY | CJ19: SATURDAY | CL19: SUNDAY | CM19: MONDAY | CN19: TUESDAY | CO19: WEDNESDAY | CP19: THURSDAY | CQ19: FRIDAY | CR19: SATURDAY
B20: =H4+1 -> 4 | C20: =B20+1 -> 5 | D20: =C20+1 -> 6 | E20: =D20+1 -> 7 | F20: =E20+1 -> 8 | G20: =F20+1 -> 9 | H20: =G20+1 -> 10 | J20: =P4+1 -> 8 | K20: =J20+1 -> 9 | L20: =K20+1 -> 10 | M20: =L20+1 -> 11 | N20: =M20+1 -> 12 | O20: =N20+1 -> 13 | P20: =O20+1 -> 14 | R20: =X4+1 -> 8 | S20: =R20+1 -> 9 | T20: =S20+1 -> 10 | U20: =T20+1 -> 11 | V20: =U20+1 -> 12 | W20: =V20+1 -> 13 | X20: =W20+1 -> 14 | Z20: =AF4+1 -> 12 | AA20: =Z20+1 -> 13 | AB20: =AA20+1 -> 14 | AC20: =AB20+1 -> 15 | AD20: =AC20+1 -> 16 | AE20: =AD20+1 -> 17 | AF20: =AE20+1 -> 18 | AH20: =AN4+1 -> 10 | AI20: =AH20+1 -> 11 | AJ20: =AI20+1 -> 12 | AK20: =AJ20+1 -> 13 | AL20: =AK20+1 -> 14 | AM20: =AL20+1 -> 15 | AN20: =AM20+1 -> 16 | AP20: =AV4+1 -> 7 | AQ20: =AP20+1 -> 8 | AR20: =AQ20+1 -> 9 | AS20: =AR20+1 -> 10 | AT20: =AS20+1 -> 11 | AU20: =AT20+1 -> 12 | AV20: =AU20+1 -> 13 | AX20: =BD4+1 -> 12 | AY20: =AX20+1 -> 13 | AZ20: =AY20+1 -> 14 | BA20: =AZ20+1 -> 15 | BB20: =BA20+1 -> 16 | BC20: =BB20+1 -> 17 | BD20: =BC20+1 -> 18 | BF20: =BL4+1 -> 9 | BG20: =BF20+1 -> 10 | BH20: =BG20+1 -> 11 | BI20: =BH20+1 -> 12 | BJ20: =BI20+1 -> 13 | BK20: =BJ20+1 -> 14 | BL20: =BK20+1 -> 15 | BN20: =BT4+1 -> 6 | BO20: =BN20+1 -> 7 | BP20: =BO20+1 -> 8 | BQ20: =BP20+1 -> 9 | BR20: =BQ20+1 -> 10 | BS20: =BR20+1 -> 11 | BT20: =BS20+1 -> 12 | BV20: =CB4+1 -> 11 | BW20: =BV20+1 -> 12 | BX20: =BW20+1 -> 13 | BY20: =BX20+1 -> 14 | BZ20: =BY20+1 -> 15 | CA20: =BZ20+1 -> 16 | CB20: =CA20+1 -> 17 | CD20: =CJ4+1 -> 8 | CE20: =CD20+1 -> 9 | CF20: =CE20+1 -> 10 | CG20: =CF20+1 -> 11 | CH20: =CG20+1 -> 12 | CI20: =CH20+1 -> 13 | CJ20: =CI20+1 -> 14 | CL20: =CR4+1 -> 6 | CM20: =CL20+1 -> 7 | CN20: =CM20+1 -> 8 | CO20: =CN20+1 -> 9 | CP20: =CO20+1 -> 10 | CQ20: =CP20+1 -> 11 | CR20: =CQ20+1 -> 12
C21: Doc | E21: Doc | G21: Doc | N21: Crystal | O21: Crystal | P21: Crystal | AA21: Dr Rally | AB21: Dr Rally | AC21: Doc | AH21: Sonora | AI21: Sonora | AJ21: Sonora | AK21: Sonora | AL21: Sonora | AM21: Sonora | AN21: Sonora | AV21: Laura | BC21: Alysia | BD21: Alysia | BH21: Ken | BK21: Ken | BN21: Dr Scott | BO21: Dr Scott | BV21: Eric | BW21: Eric | CI21: Alysia | CP21: Kirtlynn | CQ21: Kirtlynn | CR21: Kirtlynn
B22: Megan | C22: Megan | D22: Megan | E22: Megan | F22: Megan | G22: Megan | H22: Megan | K22: Lizbeth | P22: Lizbeth | X22: Dr Hab | AF22: Alysia | AI22: Adriana | AJ22: Adriana | AK22: Adriana | AL22: Adriana | AM22: Adriana | AQ22: Aislinn | AY22: Nichole | AZ22: Nichole | BA22: Nichole | BB22: Nichole | BC22: Nichole | BD22: Nichole | BF22: Doc | BG22: Doc | BH22: Doc | BI22: Doc | BJ22: Doc | BK22: Doc | BL22: Doc | BN22: Lesly | BO22: Lesly | BP22: Lesly | BQ22: Lesly | BR22: Lesly | BS22: Lesly | BT22: Lesly | CP22: Zuleyka | CQ22: Zuleyka | CR22: Zuleyka
B23: Dr Hab | C23: Dr Hab | D23: Dr Hab | E23: Dr Hab | F23: Dr Hab | G23: Dr Hab | K23: Jessica S | N23: Jessica S | P23: Jessica S | R23: Dr Scott | S23: Dr Scott | Z23: Dre | AA23: Dre | AB23: Dre | AC23: Dre | AD23: Dre | AE23: Dre | AH23: Doc | AI23: Doc | AJ23: Doc | AK23: Doc | AL23: Doc | AM23: Doc | AV23: Brittany F | AX23: Dr Rally | AY23: Dr Rally | BC23: Dr Rally | BH23: Dr Robertson | BP23: Ken
B24: Dr V | C24: Dr V | D24: Dr V | E24: Dr V | H24: Ervin | J24: Dr Lau | K24: Dr Lau | L24: Dr Lau | M24: Dr Lau | N24: Dr Lau | O24: Dr Lau | P24: Dr Lau | X24: Laura | AE24: Dr Faro | AF24: Dr Faro | AL24: Dr Lau | AM24: Dr Lau | AN24: Dr Lau | BB24: Dr Geist | BC24: Dr Geist | BD24: Dr Geist | BF24: Ken | BL24: Ali
G25: Tanya | K25: Doc | L25: Doc | M25: Doc | N25: Doc | O25: Doc | P25: Doc | W25: Dr Robertson | X25: Dr Robertson | AD25: Nauman Ali | AE25: Nauman Ali | AF25: Nauman Ali | AK25: Dr Robertson | AL25: Dr Robertson | AM25: Dr Robertson | AN25: Dr Robertson | AQ25: Carmen | AR25: Carmen | AS25: Carmen | AU25: Carmen | AV25: Carmen | AX25: Brittany F | AY25: Brittany F | AZ25: Bianca | BA25: Bianca | BB25: Bianca | BC25: Bianca | BD25: Bianca | BI25: Megan | BN25: Isabelle | BO25: Isabelle | BP25: Isabelle | BQ25: Isabelle | BR25: Isabelle | BS25: Isabelle
H26: Markie | O26: Vero | P26: Vero | X26: Dr V | AD26: Nichole | AE26: Nichole | AF26: Nichole | AL26: Alysia | AM26: Alysia | AN26: Alysia | AQ26: Christina | AR26: Christina | AS26: Christina | AT26: Christina | AU26: Christina | AX26: Aislinn | AY26: Aislinn | BG26: Fidel | BH26: Fidel | BK26: Alysia | BL26: Alysia | BO26: Zuleyka | BP26: Zuleyka | BQ26: Zuleyka | BR26: Zuleyka | BS26: Zuleyka | BT26: Zuleyka
G27: Kenny | H27: Kenny | J27: Dr Scott | K27: Dr Scott | W27: Ervin | X27: Ervin | Z27: Natalie | AA27: Natalie | AI27: Maria S | AK27: Jenn | AL27: Jenn | AM27: Jenn | AV27: Lizbeth | AX27: Lesly | AY27: Lesly | AZ27: Lesly | BA27: Lesly | BB27: Lesly | BC27: Lesly | BD27: Lesly | BF27: Isabelle | BG27: Isabelle | BH27: Isabelle | BL27: Lizbeth | BT27: Markie
G28: Caitlin | H28: Caitlin | P28: Jenn V | W28: Caitlin | X28: Caitlin | Z28: Bianca | AA28: Bianca | AF28: Laura | AL28: Aislinn | AN28: Laura | AR28: Brandon | AX28: Kirtlynn | AY28: Kirtlynn | BD28: Veronica | BJ28: Jenn V | BT28: Diana
E29: Jessica S | G29: Kirtlyn | H29: Kirtlyn | P29: Alysia | X29: Tanya | AF29: Raquel | AM29: Dr Hab | AN29: Dr Hab | AQ29: Dr Rally | AR29: Dr Rally | AS29: Dr Rally | AT29: Dr Rally | AU29: Dr Rally | AV29: Dr Rally | AX29: Ali | AY29: Ali | BC29: Lizbeth | BG29: Brandon | BK29: Brandon | BL29: Brandon
F30: Carmen | G30: Carmen | H30: Carmen | P30: Dr Hab | V30: Alexei | W30: Alexei | X30: Alexei | AF30: Zuleyka | AM30: Catherine | AN30: Catherine | AQ30: Veronica | AZ30: Dr Robertson | BF30: Dr Hab | BG30: Dr Hab | BH30: Dr Hab | BI30: Dr Hab | BJ30: Dr Hab | BK30: Dr Hab | BL30: Dr Hab
F31: Sonora | G31: Sonora | H31: Sonora | P31: Laura | X31: Dr Alzate | AE31: Zowie | AF31: Zowie | AM31: Dr Geist | AN31: Dr Geist | AP31: Kirtlynn | AQ31: Kirtlynn | AR31: Kirtlynn | AV31: Rachael | BC31: Saul | BD31: Saul | BG31: Victoria | BJ31: Victoria
D32: Dr Hoh | E32: Dr Hoh | F32: Dr Hoh | G32: Dr Hoh | H32: Dr Hoh | N32: Bianca | O32: Bianca | P32: Bianca | X32: Dr Scott | Z32: Naomi Folta | AA32: Naomi Folta | AB32: Naomi Folta | AC32: Naomi Folta | AD32: Naomi Folta | AE32: Naomi Folta | AK32: Ken | AM32: Brandon | AN32: Brandon | AU32: Dr Faro | AV32: Dr Faro | BH32: Tanya | BJ32: Tanya | BL32: Laura
F33: Dr Rally | G33: Dr Rally | J33: Dr Hoh | K33: Dr Hoh | L33: Dr Hoh | M33: Dr Hoh | N33: Dr Hoh | O33: Dr Hoh | P33: Dr Hoh | V33: Crystal | W33: Crystal | AI33: Lizbeth | AN33: Veronica | BB33: Olivia | BC33: Olivia | BD33: Olivia | BG33: Bianca | BH33: Bianca | BI33: Bianca | BJ33: Bianca | BK33: Bianca | BL33: Bianca
J34: Batia | K34: Batia | L34: Batia | M34: Batia | N34: Batia | O34: Batia | P34: Batia | AN34: Dr Scott | BC34: Tanya | BD34: Tanya | BI34: Alex M | BJ34: Alex M | BK34: Alex M | BL34: Alex M
B35: SUNDAY | C35: MONDAY | D35: TUESDAY | E35: WEDNESDAY | F35: THURSDAY | G35: FRIDAY | H35: SATURDAY | J35: SUNDAY | K35: MONDAY | L35: TUESDAY | M35: WEDNESDAY | N35: THURSDAY | O35: FRIDAY | P35: SATURDAY | R35: SUNDAY | S35: MONDAY | T35: TUESDAY | U35: WEDNESDAY | V35: THURSDAY | W35: FRIDAY | X35: SATURDAY | Z35: SUNDAY | AA35: MONDAY | AB35: TUESDAY | AC35: WEDNESDAY | AD35: THURSDAY | AE35: FRIDAY | AF35: SATURDAY | AH35: SUNDAY | AI35: MONDAY | AJ35: TUESDAY | AK35: WEDNESDAY | AL35: THURSDAY | AM35: FRIDAY | AN35: SATURDAY | AP35: SUNDAY | AQ35: MONDAY | AR35: TUESDAY | AS35: WEDNESDAY | AT35: THURSDAY | AU35: FRIDAY | AV35: SATURDAY | AX35: SUNDAY | AY35: MONDAY | AZ35: TUESDAY | BA35: WEDNESDAY | BB35: THURSDAY | BC35: FRIDAY | BD35: SATURDAY | BF35: SUNDAY | BG35: MONDAY | BH35: TUESDAY | BI35: WEDNESDAY | BJ35: THURSDAY | BK35: FRIDAY | BL35: SATURDAY | BN35: SUNDAY | BO35: MONDAY | BP35: TUESDAY | BQ35: WEDNESDAY | BR35: THURSDAY | BS35: FRIDAY | BT35: SATURDAY | BV35: SUNDAY | BW35: MONDAY | BX35: TUESDAY | BY35: WEDNESDAY | BZ35: THURSDAY | CA35: FRIDAY | CB35: SATURDAY | CD35: SUNDAY | CE35: MONDAY | CF35: TUESDAY | CG35: WEDNESDAY | CH35: THURSDAY | CI35: FRIDAY | CJ35: SATURDAY | CL35: SUNDAY | CM35: MONDAY | CN35: TUESDAY | CO35: WEDNESDAY | CP35: THURSDAY | CQ35: FRIDAY | CR35: SATURDAY
B36: =H20+1 -> 11 | C36: =B36+1 -> 12 | D36: =C36+1 -> 13 | E36: =D36+1 -> 14 | F36: =E36+1 -> 15 | G36: =F36+1 -> 16 | H36: =G36+1 -> 17 | J36: =P20+1 -> 15 | K36: =J36+1 -> 16 | L36: =K36+1 -> 17 | M36: =L36+1 -> 18 | N36: =M36+1 -> 19 | O36: =N36+1 -> 20 | P36: =O36+1 -> 21 | R36: =X20+1 -> 15 | S36: =R36+1 -> 16 | T36: =S36+1 -> 17 | U36: =T36+1 -> 18 | V36: =U36+1 -> 19 | W36: =V36+1 -> 20 | X36: =W36+1 -> 21 | Z36: =AF20+1 -> 19 | AA36: =Z36+1 -> 20 | AB36: =AA36+1 -> 21 | AC36: =AB36+1 -> 22 | AD36: =AC36+1 -> 23 | AE36: =AD36+1 -> 24 | AF36: =AE36+1 -> 25 | AH36: =AN20+1 -> 17 | AI36: =AH36+1 -> 18 | AJ36: =AI36+1 -> 19 | AK36: =AJ36+1 -> 20 | AL36: =AK36+1 -> 21 | AM36: =AL36+1 -> 22 | AN36: =AM36+1 -> 23 | AP36: =AV20+1 -> 14 | AQ36: =AP36+1 -> 15 | AR36: =AQ36+1 -> 16 | AS36: =AR36+1 -> 17 | AT36: =AS36+1 -> 18 | AU36: =AT36+1 -> 19 | AV36: =AU36+1 -> 20 | AX36: =BD20+1 -> 19 | AY36: =AX36+1 -> 20 | AZ36: =AY36+1 -> 21 | BA36: =AZ36+1 -> 22 | BB36: =BA36+1 -> 23 | BC36: =BB36+1 -> 24 | BD36: =BC36+1 -> 25 | BF36: =BL20+1 -> 16 | BG36: =BF36+1 -> 17 | BH36: =BG36+1 -> 18 | BI36: =BH36+1 -> 19 | BJ36: =BI36+1 -> 20 | BK36: =BJ36+1 -> 21 | BL36: =BK36+1 -> 22 | BN36: =BT20+1 -> 13 | BO36: =BN36+1 -> 14 | BP36: =BO36+1 -> 15 | BQ36: =BP36+1 -> 16 | BR36: =BQ36+1 -> 17 | BS36: =BR36+1 -> 18 | BT36: =BS36+1 -> 19 | BV36: =CB20+1 -> 18 | BW36: =BV36+1 -> 19 | BX36: =BW36+1 -> 20 | BY36: =BX36+1 -> 21 | BZ36: =BY36+1 -> 22 | CA36: =BZ36+1 -> 23 | CB36: =CA36+1 -> 24 | CD36: =CJ20+1 -> 15 | CE36: =CD36+1 -> 16 | CF36: =CE36+1 -> 17 | CG36: =CF36+1 -> 18 | CH36: =CG36+1 -> 19 | CI36: =CH36+1 -> 20 | CJ36: =CI36+1 -> 21 | CL36: =CR20+1 -> 13 | CM36: =CL36+1 -> 14 | CN36: =CM36+1 -> 15 | CO36: =CN36+1 -> 16 | CP36: =CO36+1 -> 17 | CQ36: =CP36+1 -> 18 | CR36: =CQ36+1 -> 19
D37: Doc | J37: Crystal | K37: Crystal | N37: Angela | O37: Angela | P37: Angela | W37: Doc | X37: Doc | AC37: Doc | AD37: Dr Rally | AE37: Dr Rally | AH37: Sonora | AI37: Sonora | AJ37: Sonora | AL37: Shelby | AM37: Shelby | AN37: Shelby | AU37: Ken | AX37: Alysia | AY37: Alysia | AZ37: Alysia | BD37: Lizbeth | BJ37: Dr Niko | BK37: Dr Niko | BL37: Dr Niko | BN37: Lesly | BR37: Dr V | BS37: Dr V | BT37: Dr V | CA37: Dr Lau | CB37: Dr Lau | CF37: Diana | CI37: Diana | CJ37: Diana | CL37: Kirtlynn | CM37: Kirtlynn
H38: Diana | K38: Lizbeth | S38: Alysia | X38: Alysia | AN38: Ashley P | AU38: Alysia | AV38: Alysia | AY38: Dr Scott | AZ38: Dr Scott | BA38: Dr Scott | BB38: Dr Scott | BC38: Dr Scott | BD38: Dr Scott | BJ38: Dr G | BK38: Dr Geist | BL38: Dr Geist | BS38: Dr Scott | BT38: Dr Scott | CH38: Dr Robertson | CI38: Dr Robertson | CJ38: Dr Robertson | CL38: Zuleyka | CM38: Zuleyka
C39: Adriana | D39: Adriana | E39: Adriana | F39: Adriana | G39: Adriana | H39: Adriana | M39: Zuleyka | N39: Zuleyka | O39: Zuleyka | P39: Zuleyka | R39: Dr Robertson | T39: Dr Robertson | AC39: Dr Hoh | AD39: Dr Hoh | AE39: Dr Hoh | AF39: Dr Hoh | AI39: Doc | AJ39: Doc | AK39: Doc | AL39: Doc | AM39: Doc | AU39: Alex M | AV39: Alex M | BB39: Nichole | BC39: Nichole | BD39: Nichole | BF39: Doc | BG39: Doc | BH39: Doc | BL39: Markie | BS39: Adriana | CE39: Dr Hab
H40: Ervin | K40: Laura | R40: Dr V | X40: Markie | Z40: Zuleyka | AA40: Zuleyka | AB40: Zuleyka | AC40: Zuleyka | AF40: Alysia | AH40: Dr Lau | AI40: Dr Lau | AJ40: Dr Lau | AK40: Dr Lau | AL40: Dr Lau | AP40: Brittany F | AQ40: Brittany F | AR40: Brittany F | AS40: Brittany F | AT40: Brittany F | AU40: Brittany F | AV40: Brittany F | AY40: Dr Rally | AZ40: Dr Rally | BA40: Dr Rally | BB40: Dr Rally | BC40: Dr Rally | BD40: Dr Rally | BF40: Dr Hab | BG40: Dr Hab | BH40: Dr Hab | BI40: Dr Hab | BJ40: Dr Hab | BS40: Jessica Lucra | CE40: Diana
B41: Kenny | H41: Ashley P | J41: Dr Lau | K41: Dr Lau | L41: Dr Lau | M41: Dr Lau | N41: Dr Lau | R41: Alexei | S41: Alexei | T41: Alexei | U41: Alexei | V41: Alexei | W41: Alexei | X41: Alexei | AD41: Vero | AE41: Vero | AF41: Vero | AL41: Diana | AM41: Diana | AN41: Diana | AV41: Diana | AX41: Dr Geist | AY41: Dr Geist | AZ41: Dr Geist | BA41: Dr Geist | BG41: Maria Salazar | BK41: Dr Lau | BL41: Dr Lau
...

Sheet ALT CAL
B1: r-[ | C1: JANUARY | K1: FEBRUARY | S1: MARCH | AA1: APRIL | AI1: MAY | AQ1: JUNE | AY1: JULY | BG1: AUGUST | BO1: SEPTEMBER | BW1: OCTOBER | CE1: NOVEMBER | CM1: DECEMBER
A2: EMPLOYEE | C2: SUNDAY | D2: MONDAY | E2: TUESDAY | F2: WEDNESDAY | G2: THURSDAY | H2: FRIDAY | I2: SATURDAY | K2: SUNDAY | L2: MONDAY | M2: TUESDAY | N2: WEDNESDAY | O2: THURSDAY | P2: FRIDAY | Q2: SATURDAY | S2: SUNDAY | T2: MONDAY | U2: TUESDAY | V2: WEDNESDAY | W2: THURSDAY | X2: FRIDAY | Y2: SATURDAY | AA2: SUNDAY | AB2: MONDAY | AC2: TUESDAY | AD2: WEDNESDAY | AE2: THURSDAY | AF2: FRIDAY | AG2: SATURDAY | AI2: SUNDAY | AJ2: MONDAY | AK2: TUESDAY | AL2: WEDNESDAY | AM2: THURSDAY | AN2: FRIDAY | AO2: SATURDAY | AQ2: SUNDAY | AR2: MONDAY | AS2: TUESDAY | AT2: WEDNESDAY | AU2: THURSDAY | AV2: FRIDAY | AW2: SATURDAY | AY2: SUNDAY | AZ2: MONDAY | BA2: TUESDAY | BB2: WEDNESDAY | BC2: THURSDAY | BD2: FRIDAY | BE2: SATURDAY | BG2: SUNDAY | BH2: MONDAY | BI2: TUESDAY | BJ2: WEDNESDAY | BK2: THURSDAY | BL2: FRIDAY | BM2: SATURDAY | BO2: SUNDAY | BP2: MONDAY | BQ2: TUESDAY | BR2: WEDNESDAY | BS2: THURSDAY | BT2: FRIDAY | BU2: SATURDAY | BW2: SUNDAY | BX2: MONDAY | BY2: TUESDAY | BZ2: WEDNESDAY | CA2: THURSDAY | CB2: FRIDAY | CC2: SATURDAY | CE2: SUNDAY | CF2: MONDAY | CG2: TUESDAY | CH2: WEDNESDAY | CI2: THURSDAY | CJ2: FRIDAY | CK2: SATURDAY | CM2: SUNDAY | CN2: MONDAY | CO2: TUESDAY | CP2: WEDNESDAY | CQ2: THURSDAY | CR2: FRIDAY | CS2: SATURDAY
C3: 28 | D3: 29 | E3: 30 | F3: 31 | G3: 1 | H3: 2 | I3: 3 | K3: 1 | L3: 2 | M3: 3 | N3: 4 | O3: 5 | P3: 6 | Q3: 7 | S3: 1 | T3: 2 | U3: 3 | V3: 4 | W3: 5 | X3: 6 | Y3: 7 | Z3: 5 | AA3: 5 | AB3: 6 | AC3: 7 | AD3: 8 | AE3: 9 | AF3: 10 | AG3: 11 | AI3: 3 | AJ3: 4 | AK3: 5 | AL3: 6 | AM3: 7 | AN3: 8 | AO3: 9 | AQ3: 31 | AR3: 1 | AS3: 2 | AT3: 3 | AU3: 4 | AV3: 5 | AW3: 6 | AY3: 5 | AZ3: 6 | BA3: 7 | BB3: 8 | BC3: 9 | BD3: 10 | BE3: 11 | BG3: 2 | BH3: 3 | BI3: 4 | BJ3: 5 | BK3: 6 | BL3: 7 | BM3: 8 | BO3: 30 | BP3: 31 | BQ3: 1 | BR3: 2 | BS3: 3 | BT3: 4 | BU3: 5 | BW3: 4 | BX3: 5 | BY3: 6 | BZ3: 7 | CA3: 8 | CB3: 9 | CC3: 10 | CE3: 1 | CF3: 2 | CG3: 3 | CH3: 4 | CI3: 5 | CJ3: 6 | CK3: 7 | CM3: 29 | CN3: 30 | CO3: 1 | CP3: 2 | CQ3: 3 | CR3: 4 | CS3: 5
A4: Cynthia (Legal) 1pm-9pm | C4: Emergencies only | D4: Remote/ Available | E4: Remote/ Available | F4: Remote/ Available | G4: Remote/ Available | H4: Remote/ Available | I4: Emergencies only | K4: Emergencies only | L4: Remote/ Available | M4: Remote/ Available | N4: Remote/ Available | O4: Remote/ Available | P4: Remote/ Available | Q4: Emergencies only | S4: Emergencies only | T4: Remote/ Available | U4: Remote/ Available | V4: Remote/ Available | W4: Remote/ Available | X4: Remote/ Available | Y4: Emergencies only | AA4: Off | AB4: Off | AC4: Off | AD4: Off | AE4: Off | AF4: Off | AG4: Off | AI4: Emergencies only | AO4: Emergencies only | AQ4: Emergencies only | AW4: Emergencies only | AY4: Emergencies only | BE4: Emergencies only | BG4: Emergencies only | BM4: Emergencies only | BO4: Emergencies only | BU4: Emergencies only | BW4: Emergencies only | CC4: Emergencies only | CE4: Emergencies only | CK4: Emergencies only | CM4: Emergencies only | CS4: Emergencies only
A5: Gladys (CCO) | C5: If need-Remote | D5: Remote/ Available | E5: Remote/ Available | G5: Remote/ Available | H5: Remote/ Available | I5: Emergencies only | AA5: Unavailable | AB5: Unavailable | AC5: Unavailable | AJ5: Remote/ Available | AK5: Remote/ Available | AL5: Remote/ Available | AM5: Remote/ Available | AN5: Remote/ Available
A6: Marc (COO) | C6: If need-Remote | D6: Aetna/Ven | E6: Aetna/Ven | F6: Out Early | G6: If need-Remote | H6: Aetna/Ven | I6: As Needed | K6: As Needed | L6: Aetna/Ven | M6: Aetna/Ven | N6: Aetna/Ven | O6: Aetna/Ven | P6: Aetna/Ven | Q6: As Needed | S6: As Needed | T6: Aetna/Ven | U6: Aetna/Ven | V6: Aetna/Ven | W6: Aetna/Ven | X6: Aetna/Ven | Y6: As Needed | AA6: Remote/ Available | AB6: Aetna/Ven | AC6: Aetna/Ven | AD6: Aetna/Ven | AE6: If need-Remote | AF6: If need-Remote | AG6: Unavailable | AI6: If need-Remote | AJ6: Aetna/Ven | AK6: Aetna/Ven | AL6: Aetna/Ven | AM6: Aetna/Ven | AN6: Aetna/Ven | AO6: As Needed | AQ6: As Needed | AR6: Aetna/Ven | AS6: Aetna/Ven | AT6: Aetna/Ven | AU6: Aetna/Ven | AV6: Aetna/Ven | AW6: Unavailable | AY6: Unavailable | AZ6: Aetna/Ven | BA6: Aetna/Ven | BB6: Aetna/Ven | BC6: Aetna/Ven | BD6: Aetna/Ven | BE6: As Needed | BG6: Unavailable | BH6: Aetna/Ven | BI6: Aetna/Ven | BJ6: Aetna/Ven | BK6: Aetna/Ven | BL6: Aetna/Ven | BM6: As Needed | BO6: OFF GRID- BM | BP6: OFF GRID- BM | BQ6: OFF GRID- BM | BR6: OFF GRID- BM | BS6: OFF GRID- BM | BT6: OFF GRID- BM | BU6: OFF GRID- BM
A7: Angie (Schedule Admin) | C7: Remote/ Available | D7: Remote/ Available | E7: Remote/ Available | F7: Remote/ Available | G7: Off | H7: Remote/ Available | I7: Remote/ Available | L7: Remote/ Available | M7: Remote/ Available | N7: Remote/ Available | O7: Remote/ Available | P7: Remote/ Available | Q7: Remote/ Available | T7: Remote/ Available | U7: Remote/ Available | V7: Remote/ Available | W7: Remote/ Available | X7: Remote/ Available | Y7: Remote/ Available | AB7: Remote/ Available | AC7: Remote/ Available | AD7: Remote/ Available | AE7: Remote/ Available | AF7: Remote/ Available | AG7: Remote/ Available | AJ7: Remote/ Available | AK7: Remote/ Available | AL7: Remote/ Available | AM7: Remote/ Available | AN7: Remote/ Available | AO7: Remote/ Available
A8: Christina (Remote Admin)
A9: Dre (Marketing Dir) | L9: Remote/ Available | M9: Venice/ Aetna | N9: Venice/ Aetna | O9: Out Early | P9: Remote/ Available | Q9: Remote/ Available | S9: As Needed | T9: Remote | U9: Aetna/Ven | V9: Aetna/Ven | W9: Aetna/Ven | X9: Remote | Y9: As Needed | AB9: Remote | AC9: Off | AD9: Off | AE9: Off | AF9: Off | AG9: Off | AJ9: Remote | AK9: Remote | AL9: Aetna/Ven | AM9: Aetna/Ven | AN9: Remote | AO9: Off | AR9: Remote | AS9: Remote | AT9: Aetna/Ven | AU9: Aetna/Ven | AV9: Remote
C11: SUNDAY | D11: MONDAY | E11: TUESDAY | F11: WEDNESDAY | G11: THURSDAY | H11: FRIDAY | I11: SATURDAY | K11: SUNDAY | L11: MONDAY | M11: TUESDAY | N11: WEDNESDAY | O11: THURSDAY | P11: FRIDAY | Q11: SATURDAY | S11: SUNDAY | T11: MONDAY | U11: TUESDAY | V11: WEDNESDAY | W11: THURSDAY | X11: FRIDAY | Y11: SATURDAY | AA11: SUNDAY | AB11: MONDAY | AC11: TUESDAY | AD11: WEDNESDAY | AE11: THURSDAY | AF11: FRIDAY | AG11: SATURDAY | AI11: SUNDAY | AJ11: MONDAY | AK11: TUESDAY | AL11: WEDNESDAY | AM11: THURSDAY | AN11: FRIDAY | AO11: SATURDAY | AQ11: SUNDAY | AR11: MONDAY | AS11: TUESDAY | AT11: WEDNESDAY | AU11: THURSDAY | AV11: FRIDAY | AW11: SATURDAY | AY11: SUNDAY | AZ11: MONDAY | BA11: TUESDAY | BB11: WEDNESDAY | BC11: THURSDAY | BD11: FRIDAY | BE11: SATURDAY | BG11: SUNDAY | BH11: MONDAY | BI11: TUESDAY | BJ11: WEDNESDAY | BK11: THURSDAY | BL11: FRIDAY | BM11: SATURDAY | BO11: SUNDAY | BP11: MONDAY | BQ11: TUESDAY | BR11: WEDNESDAY | BS11: THURSDAY | BT11: FRIDAY | BU11: SATURDAY | BW11: SUNDAY | BX11: MONDAY | BY11: TUESDAY | BZ11: WEDNESDAY | CA11: THURSDAY | CB11: FRIDAY | CC11: SATURDAY | CE11: SUNDAY | CF11: MONDAY | CG11: TUESDAY | CH11: WEDNESDAY | CI11: THURSDAY | CJ11: FRIDAY | CK11: SATURDAY | CM11: SUNDAY | CN11: MONDAY | CO11: TUESDAY | CP11: WEDNESDAY | CQ11: THURSDAY | CR11: FRIDAY | CS11: SATURDAY
